Workbook

Sheet README
A1: Lab Waste Segregator - taxonomy and item table
A2: Purpose | B2: Starter data for a rule-based lab waste segregator. The rules decide the bin; an LLM (if used) only parses messy input and explains the answer.
A3: Status | B3: DRAFT. Categories, containers and colours are ILLUSTRATIVE (UK-style defaults). Replace them with your institution's waste policy before relying on any output.
A4: Confidence column | B4: High = standard across most institutions. Medium = common practice, local policy varies. Verify locally = policy differs materially between sites; confirm before use.
A5: Editing | B5: Blue text = editable inputs. Black text = formulas (category name and container are looked up from the Categories sheet, so changing a container there updates every item).
A6: Sheets | B6: Categories (every waste type, with its primary route and item count) | Routes (what happens to waste after it leaves your hands) | Items (one row per waste item) | Incompatibilities (pairwise mixing rules on hazard flags) | Workflows (experiment mode: what each experiment generates).
A7: Routes | B7: Each category has one primary route (Categories column I). Some have a secondary option described in Routes, e.g. BIO-LIQ can be chemically inactivated then drained (R04) or autoclaved (R02); BIO-AUT can use alternative treatment (R08) at sites without an autoclave. Filter Categories by Route ID to see which waste types share a route.
A8: Engine logic | B8: 1) Match user input to an Item (search terms). 2) Return its Category and handling steps. 3) Apply hard constraints below. 4) For mixed containers, check every flag pair in Incompatibilities. 5) If no confident match, return UNK.
A9: Hard constraints | B9: Items flagged NO_DRAIN can never route to a category with DRAIN_ROUTE. Items flagged NO_AUTOCLAVE can never route to a category with AUTOCLAVE_ROUTE. Items flagged CYTOTOXIC or CMR never share a container with anything outside their stream.
A10: Flag vocabulary | B10: BIOHAZARD, GM, SHARP, FLAMMABLE, ORGANIC, NONHAL, HALOGENATED, PHENOL, GUANIDINE, AZIDE, AMMONIA, ACID, BASE, BLEACH, OXIDISER, FORMALDEHYDE, CORROSIVE, TOXIC, IRRITANT, CARCINOGEN, MUTAGEN, CYTOTOXIC, RADIOACTIVE, WATER_REACTIVE, PEROXIDE_FORMER, EXPLOSIVE, HEAVY_METAL, PRESSURISED, NO_DRAIN, NO_AUTOCLAVE. CMR in Incompatibilities means any of CARCINOGEN, MUTAGEN.
A11: Out of scope | B11: Radioactive, animal and high-containment waste appear as escalate-only categories (RAD, ANI, HICON): the tool names them but never classifies or advises on handling beyond escalating. Controlled drugs also need a separate legal process.
A12: Assumptions | B12: Hazard flags and rules are written from general lab-safety practice and are not copied from any one institution's policy. Cross-check chemical hazards against the supplier SDS or PubChem GHS data, and clinical waste colours against local guidance (e.g. UK HTM 07-01).
A13: Example row | B13: See Items row 2 (I001): a typical entry showing ID, search terms, category ID, handling, flags, 'do not' note, rationale and confidence.

Sheet Categories
A1: Category ID | B1: Name | C1: Includes | D1: Container (illustrative) | E1: Colour (hex) | F1: Handling rules | G1: Escalation / notes | H1: Route flag | I1: Route ID | J1: Primary route | K1: Items (#)
A2: GEN | B2: General (non-hazardous) waste | C2: Items with no biological, chemical or radiological contact | D2: Black bag | E2: 333333 | F2: Only for genuinely uncontaminated items. If in doubt, do not default to this bin. | G2: If any doubt, choose UNK, not GEN. | I2: R29 | J2: =INDEX(Routes!$C$2:$C$39,MATCH(I2,Routes!$A$2:$A$39,0)) | K2: =COUNTIF(Items!$D$2:$D$86,A2)
A3: REC | B3: Dry recycling | C3: Clean cardboard, paper and clean unused plastic packaging | D3: Recycling bin (blue) | E3: 2874A6 | F3: Empty, dry, hazard labels removed. | G3: Anything that touched samples or reagents is not recycling. | I3: R26 | J3: =INDEX(Routes!$C$2:$C$39,MATCH(I3,Routes!$A$2:$A$39,0)) | K3: =COUNTIF(Items!$D$2:$D$86,A3)
A4: GLS | B4: Clean glass | C4: Uncontaminated glass, rinsed empty bottles, uncontaminated broken glass | D4: Glass / broken-glass box | E4: 7DCEA0 | F4: Triple-rinse empty chemical bottles (rinsate goes to the correct liquid stream), deface labels. Broken glass goes in a rigid box, never a bag. | G4: Contaminated glass goes to a sharps category instead. | I4: R27 | J4: =INDEX(Routes!$C$2:$C$39,MATCH(I4,Routes!$A$2:$A$39,0)) | K4: =COUNTIF(Items!$D$2:$D$86,A4)
A5: BIO-AUT | B5: Biological solids - autoclave route | C5: Consumables that touched non-GM biological material (cell culture, lysates, PCR template) | D5: Autoclave bag in rigid bin (orange / per local scheme) | E5: F39C12 | F5: Aspirate free liquid first. Bag loosely, add autoclave indicator tape, autoclave before disposal. | G5: Never add solvents, bleach, guanidinium, formaldehyde or cytotoxics. | H5: AUTOCLAVE_ROUTE | I5: R01 | J5: =INDEX(Routes!$C$2:$C$39,MATCH(I5,Routes!$A$2:$A$39,0)) | K5: =COUNTIF(Items!$D$2:$D$86,A5)
A6: BIO-GM | B6: GM / transduced material - inactivate | C6: Transfected or virally transduced cells and GM-contaminated consumables and liquids | D6: Labelled GM autoclave bag | E6: D68910 | F6: Inactivate (validated autoclave cycle or chemical) before it leaves the lab. Viral vectors follow the containment-level SOP. Label as GM. | G6: Follow the lab's GM risk assessment. | H6: AUTOCLAVE_ROUTE | I6: R03 | J6: =INDEX(Routes!$C$2:$C$39,MATCH(I6,Routes!$A$2:$A$39,0)) | K6: =COUNTIF(Items!$D$2:$D$86,A6)
A7: BIO-INC | B7: Biological - incineration | C7: Human or animal tissue, FFPE blocks, unfixed samples, anatomical waste | D7: Yellow clinical waste bin / bag | E7: F4D03F | F7: Seal, label, hold for clinical waste collection. | G7: Follow the institution's human tissue and clinical waste policy. | H7: INCINERATION_ROUTE | I7: R07 | J7: =INDEX(Routes!$C$2:$C$39,MATCH(I7,Routes!$A$2:$A$39,0)) | K7: =COUNTIF(Items!$D$2:$D$86,A7)
A8: BIO-LIQ | B8: Biological liquids | C8: Aspirated media, supernatants, PBS/trypsin washes with biological material and no hazardous additives | D8: Aspirator flask containing disinfectant | E8: 48C9B0 | F8: Inactivate with hypochlorite at the validated concentration and contact time in your SOP, then drain; or autoclave in a suitable vessel (never once bleach is added). | G8: Hazardous additives (solvents, guanidinium, azide, cytotoxics) mean it is NOT this category. | I8: R04 | J8: =INDEX(Routes!$C$2:$C$39,MATCH(I8,Routes!$A$2:$A$39,0)) | K8: =COUNTIF(Items!$D$2:$D$86,A8)
A9: SHP-INF | B9: Sharps - biological | C9: Needles, scalpel blades, broken glass or slides contaminated with biological material | D9: Sharps bin (orange lid) | E9: E67E22 | F9: Do not recap or bend. Fill to the line only. Close and label when full. | I9: R10 | J9: =INDEX(Routes!$C$2:$C$39,MATCH(I9,Routes!$A$2:$A$39,0)) | K9: =COUNTIF(Items!$D$2:$D$86,A9)
A10: SHP-CHEM | B10: Sharps - chemical / fixative | C10: Sharps and fragile glass contaminated with chemicals, fixatives or mounting media | D10: Sharps bin (yellow lid) | E10: F7DC6F | F10: As for biological sharps; write the contaminant on the label. | G10: CMR-contaminated sharps: label clearly and notify the waste coordinator. | I10: R11 | J10: =INDEX(Routes!$C$2:$C$39,MATCH(I10,Routes!$A$2:$A$39,0)) | K10: =COUNTIF(Items!$D$2:$D$86,A10)
A11: CHEM-NH | B11: Non-halogenated solvents | C11: Ethanol, methanol, isopropanol, acetone, acetonitrile, xylene, DMSO and mixtures of these | D11: Flammable solvent carboy | E11: 5DADE2 | F11: Keep halogenated solvents out. Vented cap, fume cupboard for decanting, list every constituent on the label. | G11: Never add oxidisers (bleach, nitric acid, peroxide). | I11: R15 | J11: =INDEX(Routes!$C$2:$C$39,MATCH(I11,Routes!$A$2:$A$39,0)) | K11: =COUNTIF(Items!$D$2:$D$86,A11)
A12: CHEM-HAL | B12: Halogenated solvents (incl. phenol-chloroform) | C12: Chloroform, dichloromethane, phenol-chloroform, TRIzol organic phase | D12: Halogenated solvent carboy (glass / solvent-resistant) | E12: A569BD | F12: Fume cupboard. Keep separate from non-halogenated solvents (different disposal route). | G12: Never bleach or acidify. | I12: R16 | J12: =INDEX(Routes!$C$2:$C$39,MATCH(I12,Routes!$A$2:$A$39,0)) | K12: =COUNTIF(Items!$D$2:$D$86,A12)
A13: CHEM-AQ | B13: Hazardous aqueous | C13: Aqueous solutions with toxic or irritant solutes (azide, iodoacetamide, detergent lysates, reactive reagents) | D13: Labelled aqueous waste carboy | E13: 85C1E9 | F13: Collect, list all constituents, keep azide away from acids and metal. | G13: Never down the drain. | I13: R18 | J13: =INDEX(Routes!$C$2:$C$39,MATCH(I13,Routes!$A$2:$A$39,0)) | K13: =COUNTIF(Items!$D$2:$D$86,A13)
A14: CHEM-ACID | B14: Acid waste | C14: Strong or concentrated acids (HCl, H2SO4, HNO3, neat TFA or formic acid) | D14: Acid-compatible labelled carboy | E14: EC7063 | F14: Keep apart from bases, bleach, azide, cyanides and organics. | G14: Do not neutralise unless your SOP permits. | I14: R19 | J14: =INDEX(Routes!$C$2:$C$39,MATCH(I14,Routes!$A$2:$A$39,0)) | K14: =COUNTIF(Items!$D$2:$D$86,A14)
A15: CHEM-BASE | B15: Alkaline waste | C15: Strong bases (NaOH, KOH solutions roughly pH 11 and above) | D15: Base-compatible labelled carboy | E15: F1948A | F15: Keep apart from acids and aluminium. | G15: Do not neutralise unless your SOP permits. | I15: R20 | J15: =INDEX(Routes!$C$2:$C$39,MATCH(I15,Routes!$A$2:$A$39,0)) | K15: =COUNTIF(Items!$D$2:$D$86,A15)
A16: CHEM-GUA | B16: Guanidinium / phenol lysis waste | C16: TRIzol and TRI Reagent aqueous phase and lysate, guanidinium-containing kit lysis and binding buffers and flow-through | D16: Dedicated labelled carboy (not shared with bleach waste) | E16: AF601A | F16: Own stream. Never bleach, never acidify, never autoclave. | G16: Check the kit safety sheet for which buffers contain guanidinium. | I16: R17 | J16: =INDEX(Routes!$C$2:$C$39,MATCH(I16,Routes!$A$2:$A$39,0)) | K16: =COUNTIF(Items!$D$2:$D$86,A16)
A17: CHEM-SOL | B17: Chemically contaminated solids | C17: Gloves, tips, tubes, columns, membranes, paper contaminated with hazardous chemicals | D17: Rigid labelled chemical solid waste bin / double bag | E17: ABB2B9 | F17: Drain free liquid first. Never autoclave. Keep CMR items separate. | I17: R21 | J17: =INDEX(Routes!$C$2:$C$39,MATCH(I17,Routes!$A$2:$A$39,0)) | K17: =COUNTIF(Items!$D$2:$D$86,A17)
A18: CMR-LIQ | B18: CMR liquids (carcinogen / mutagen / reprotoxic) | C18: Ethidium bromide solutions, formaldehyde / PFA, DAB, unpolymerised acrylamide, trypan blue | D18: Sealed labelled bottle in secondary containment | E18: C0392B | F18: Own stream. Never drain. Some sites require specific inactivation or filtration first. | G18: Check the SDS for H340 / H350 / H360 hazard statements. | I18: R22 | J18: =INDEX(Routes!$C$2:$C$39,MATCH(I18,Routes!$A$2:$A$39,0)) | K18: =COUNTIF(Items!$D$2:$D$86,A18)
A19: CMR-SOL | B19: CMR solids | C19: Gels, gloves, tubes, slides and paper contaminated with CMR agents | D19: Sealed labelled bin / double bag | E19: E74C3C | F19: Own stream. Never autoclave, never general waste. | I19: R22 | J19: =INDEX(Routes!$C$2:$C$39,MATCH(I19,Routes!$A$2:$A$39,0)) | K19: =COUNTIF(Items!$D$2:$D$86,A19)
A20: CYT | B20: Cytotoxic / cytostatic | C20: Cells, media and consumables exposed to cytotoxic drugs (cisplatin, doxorubicin, etc.) | D20: Purple-lidded bin / purple bag | E20: 6C3483 | F20: Never autoclave or bleach-and-drain. Purple stream for incineration. | G20: Purple-lidded sharps bins for sharps. | H20: INCINERATION_ROUTE | I20: R14 | J20: =INDEX(Routes!$C$2:$C$39,MATCH(I20,Routes!$A$2:$A$39,0)) | K20: =COUNTIF(Items!$D$2:$D$86,A20)
A21: RAD | B21: Radioactive - OUT OF SCOPE | C21: Any radiolabelled material | D21: Do not dispose - refer to Radiation Protection Supervisor | E21: 239B56 | F21: The tool must not classify this. Escalate. | G21: Always escalate. | I21: R30 | J21: =INDEX(Routes!$C$2:$C$39,MATCH(I21,Routes!$A$2:$A$39,0)) | K21: =COUNTIF(Items!$D$2:$D$86,A21)
A22: DRAIN | B22: Non-hazardous aqueous - drain with flush | C22: Near-neutral buffers with no azide, solvents, metals, biological material or hazardous additives; dilute used bleach | D22: Sink (flush with plenty of water) | E22: D6EAF8 | F22: Small volumes only, roughly pH 6-10, run water before and after. Local trade-effluent rules apply. | G22: Any item flagged NO_DRAIN must never land here. | H22: DRAIN_ROUTE | I22: R06 | J22: =INDEX(Routes!$C$2:$C$39,MATCH(I22,Routes!$A$2:$A$39,0)) | K22: =COUNTIF(Items!$D$2:$D$86,A22)
A23: UNK | B23: Unsure - escalate | C23: Unlabelled, unidentified or unmatched items | D23: Do not dispose - label and quarantine | E23: 17202A | F23: Ask the supervisor or safety officer. The tool defaults here when confidence is low. | G23: This is the safe fallback. | I23: R38 | J23: =INDEX(Routes!$C$2:$C$39,MATCH(I23,Routes!$A$2:$A$39,0)) | K23: =COUNTIF(Items!$D$2:$D$86,A23)
A24: SHP-CYT | B24: Sharps - cytotoxic | C24: Needles, syringes and glass used with cytotoxic drugs | D24: Sharps bin (purple lid) | E24: 8E44AD | F24: As for biological sharps; never mix with other sharps. | G24: Incinerated via the cytotoxic stream. | H24: INCINERATION_ROUTE | I24: R12 | J24: =INDEX(Routes!$C$2:$C$39,MATCH(I24,Routes!$A$2:$A$39,0)) | K24: =COUNTIF(Items!$D$2:$D$86,A24)
A25: PHARM | B25: Pharmaceutical (non-cytotoxic) | C25: Expired or unused non-cytotoxic medicines and veterinary drugs | D25: Pharmaceutical waste bin (blue lid) | E25: 3498DB | F25: Keep in original packaging where possible. Never drain. | G25: Controlled drugs follow a separate legal process - escalate. | H25: INCINERATION_ROUTE | I25: R09 | J25: =INDEX(Routes!$C$2:$C$39,MATCH(I25,Routes!$A$2:$A$39,0)) | K25: =COUNTIF(Items!$D$2:$D$86,A25)
A26: REACT | B26: Reactive / unstable chemicals | C26: Water-reactive reagents (acetic anhydride, acid chlorides), peroxide formers past date, azide solids, dry or old picric acid | D26: Own labelled container; vented cap if the site uses them | E26: FF5733 | F26: Never combine with any other waste. Fume cupboard. Quench only under an approved SOP by trained staff. | G26: If crystals are visible or the container is old, do not move it - call the safety officer. | I26: R23 | J26: =INDEX(Routes!$C$2:$C$39,MATCH(I26,Routes!$A$2:$A$39,0)) | K26: =COUNTIF(Items!$D$2:$D$86,A26)
A27: LABPACK | B27: Surplus reagents (lab pack) | C27: Unwanted or surplus reagents kept in their original, labelled containers | D27: Original container, listed on the lab-pack inventory | E27: A04000 | F27: Do not decant or combine. Keep the label legible, list on the inventory, store by hazard class. | G27: Collected by the specialist contractor as a lab pack. | I27: R24 | J27: =INDEX(Routes!$C$2:$C$39,MATCH(I27,Routes!$A$2:$A$39,0)) | K27: =COUNTIF(Items!$D$2:$D$86,A27)
A28: METAL | B28: Heavy-metal waste | C28: Mercury, cadmium, lead, chromium(VI), silver and similar metal-containing solutions and solids | D28: Labelled metal-waste container | E28: 7F8C8D | F28: Own stream. Never drain. Keep apart from azide. | G28: Silver stain waste belongs here. | I28: R25 | J28: =INDEX(Routes!$C$2:$C$39,MATCH(I28,Routes!$A$2:$A$39,0)) | K28: =COUNTIF(Items!$D$2:$D$86,A28)
A29: TAKEBACK | B29: Supplier take-back packaging | C29: Polystyrene boxes, clean ice or cool packs, some tip racks and reagent packaging | D29: Collection point / return to supplier | E29: A9DFBF | F29: Clean and dry; remove labels where required. | G29: Only where the supplier runs a scheme - otherwise recycling or general waste. | I29: R28 | J29: =INDEX(Routes!$C$2:$C$39,MATCH(I29,Routes!$A$2:$A$39,0)) | K29: =COUNTIF(Items!$D$2:$D$86,A29)
A30: REUSE | B30: Reuse / redistribute | C30: Unopened, in-date surplus reagents and consumables | D30: Chemical exchange shelf / board | E30: ABEBC6 | F30: Advertise to other labs before disposal; check expiry and storage conditions. | G30: Not for opened, expired or unlabelled items. | I30: R37 | J30: =INDEX(Routes!$C$2:$C$39,MATCH(I30,Routes!$A$2:$A$39,0)) | K30: =COUNTIF(Items!$D$2:$D$86,A30)
A31: WEEE | B31: Electrical and electronic equipment (WEEE) | C31: Old plate readers, pipette controllers, power supplies, small instruments | D31: WEEE collection (tagged) | E31: 566573 | F31: Decontaminate and tag as safe before collection. | G31: Contact the estates or equipment team. | I31: R31 | J31: =INDEX(Routes!$C$2:$C$39,MATCH(I31,Routes!$A$2:$A$39,0)) | K31: =COUNTIF(Items!$D$2:$D$86,A31)
A32: BATT | B32: Batteries | C32: Instrument, pipette controller and remote batteries | D32: Battery collection tub | E32: F5B041 | F32: Tape the terminals of lithium cells. Do not bin. | I32: R32 | J32: =INDEX(Routes!$C$2:$C$39,MATCH(I32,Routes!$A$2:$A$39,0)) | K32: =COUNTIF(Items!$D$2:$D$86,A32)
A33: LAMP | B33: Lamps and tubes | C33: UV bulbs, fluorescent tubes, transilluminator lamps | D33: Lamp collection box | E33: F9E79F | F33: Handle carefully; many contain mercury. | I33: R33 | J33: =INDEX(Routes!$C$2:$C$39,MATCH(I33,Routes!$A$2:$A$39,0)) | K33: =COUNTIF(Items!$D$2:$D$86,A33)
A34: CYL | B34: Gas cylinders | C34: Empty or unwanted CO2, nitrogen, argon and other cylinders | D34: Return to supplier / designated cylinder store | E34: 5499C7 | F34: Close valve, cap, label as empty or full, store upright and secured. | G34: Never dispose of locally. | I34: R34 | J34: =INDEX(Routes!$C$2:$C$39,MATCH(I34,Routes!$A$2:$A$39,0)) | K34: =COUNTIF(Items!$D$2:$D$86,A34)
A35: ANI | B35: Animal waste - OUT OF SCOPE | C35: Carcasses, bedding and in-vivo waste | D35: Do not dispose - follow the animal facility procedure | E35: 145A32 | F35: The tool must not classify this. Escalate. | G35: Always escalate. | I35: R35 | J35: =INDEX(Routes!$C$2:$C$39,MATCH(I35,Routes!$A$2:$A$39,0)) | K35: =COUNTIF(Items!$D$2:$D$86,A35)
A36: HICON | B36: High-containment pathogens - OUT OF SCOPE | C36: Pathogens above containment level 2 or unknown pathogens | D36: Do not dispose - follow the containment facility procedure | E36: 7B241C | F36: The tool must not classify this. Escalate. | G36: Always escalate. | I36: R36 | J36: =INDEX(Routes!$C$2:$C$39,MATCH(I36,Routes!$A$2:$A$39,0)) | K36: =COUNTIF(Items!$D$2:$D$86,A36)

Sheet Routes
A1: Route ID | B1: Group | C1: Route | D1: What happens | E1: Typical waste | F1: Container / marking (illustrative) | G1: Categories using this route (#)
A2: R01 | B2: 1 Treat in lab | C2: Autoclave (solids) | D2: Bagged solids are autoclaved on a validated cycle, then collected as treated waste. | E2: Cell culture plastics, tips, tubes, plates | F2: Autoclave bag in rigid bin, indicator tape | G2: =COUNTIF(Categories!$I$2:$I$36,A2)
A3: R02 | B3: 1 Treat in lab | C3: Autoclave (liquids, vented vessel) | D3: Liquids autoclaved in a suitable vented vessel on a liquid cycle, then drained or collected. Never after bleach is added. | E3: Culture media with no hazardous additives | F3: Autoclavable vessel with vented cap | G3: =COUNTIF(Categories!$I$2:$I$36,A3)
A4: R03 | B4: 1 Treat in lab | C4: Validated GM inactivation | D4: Autoclave or validated chemical inactivation before leaving the lab, per the GM risk assessment. | E4: Transfected or transduced cells and consumables | F4: Labelled GM bag | G4: =COUNTIF(Categories!$I$2:$I$36,A4)
A5: R04 | B5: 1 Treat in lab | C5: Chemical inactivation then drain | D5: Hypochlorite or approved disinfectant at validated concentration and contact time, then drain with flush. | E5: Aspirated media, supernatants | F5: Aspirator flask with disinfectant | G5: =COUNTIF(Categories!$I$2:$I$36,A5)
A6: R05 | B6: 1 Treat in lab | C6: Chemical disinfectant soak | D6: Reusable items soaked in approved disinfectant for the validated contact time, then washed. | E6: Reusable glass, forceps, racks | F6: Soak tub with fresh disinfectant | G6: =COUNTIF(Categories!$I$2:$I$36,A6)
A7: R06 | B7: 2 Drain | C7: Drain with flush | D7: Small volumes of non-hazardous aqueous waste flushed with plenty of water. | E7: Neutral buffers (TBST, TAE, running buffer), diluted used bleach | F7: Sink | G7: =COUNTIF(Categories!$I$2:$I$36,A7)
A8: R07 | B8: 3 Clinical / biological collection | C8: Clinical incineration (yellow) | D8: Sealed, labelled and collected by the clinical waste contractor for incineration. | E8: Tissue, FFPE, unfixed human or animal samples | F8: Yellow bin or bag | G8: =COUNTIF(Categories!$I$2:$I$36,A8)
A9: R08 | B9: 3 Clinical / biological collection | C9: Alternative treatment (orange) | D9: Infectious solids collected for off-site treatment instead of lab autoclaving. Used by sites without an autoclave. | E9: Infectious solids | F9: Orange bag | G9: =COUNTIF(Categories!$I$2:$I$36,A9)
A10: R09 | B10: 3 Clinical / biological collection | C10: Pharmaceutical collection (blue) | D10: Collected for pharmaceutical incineration. | E10: Non-cytotoxic medicines | F10: Blue-lidded bin | G10: =COUNTIF(Categories!$I$2:$I$36,A10)
A11: R10 | B11: 4 Sharps | C11: Sharps - biological (orange lid) | D11: Bin filled to the line, closed and collected for treatment. | E11: Needles, blades, contaminated glass | F11: Orange-lidded sharps bin | G11: =COUNTIF(Categories!$I$2:$I$36,A11)
A12: R11 | B12: 4 Sharps | C12: Sharps - chemical (yellow lid) | D12: Bin filled to the line, closed and collected for incineration. | E12: Stain-contaminated glass, EtBr blades | F12: Yellow-lidded sharps bin | G12: =COUNTIF(Categories!$I$2:$I$36,A12)
A13: R12 | B13: 4 Sharps | C13: Sharps - cytotoxic (purple lid) | D13: Collected with cytotoxic waste for incineration. | E13: Needles used with cytotoxic drugs | F13: Purple-lidded sharps bin | G13: =COUNTIF(Categories!$I$2:$I$36,A13)
... A39: R38 | B39: 9 Non-disposal | C39: Hold and escalate | D39: Item is quarantined and referred to the supervisor or safety officer. The tool's safe fallback. | E39: Unlabelled, unidentified or unmatched items | F39: Label and quarantine | G39: =COUNTIF(Categories!$I$2:$I$36,A39)

Sheet Items
A1: Item ID | B1: Item | C1: Search terms / aliases | D1: Category ID | E1: Category | F1: Container | G1: Pre-treatment / steps | H1: Hazard flags | I1: Do NOT | J1: Why (one line) | K1: Confidence
A2: I001 | B2: Used gloves - no biological or chemical contact | C2: nitrile gloves, PPE, latex | D2: GEN | E2: =INDEX(Categories!$B$2:$B$36,MATCH(D2,Categories!$A$2:$A$36,0)) | F2: =INDEX(Categories!$D$2:$D$36,MATCH(D2,Categories!$A$2:$A$36,0)) | G2: Remove without touching the outer surface. | I2: Not if the gloves touched cell culture, reagents or lysates. | J2: Nothing hazardous present. | K2: Medium
A3: I002 | B3: Bench roll / paper towels - uncontaminated | C3: tissue, blue roll | D3: GEN | E3: =INDEX(Categories!$B$2:$B$36,MATCH(D3,Categories!$A$2:$A$36,0)) | F3: =INDEX(Categories!$D$2:$D$36,MATCH(D3,Categories!$A$2:$A$36,0)) | J3: Nothing hazardous present. | K3: High
A4: I003 | B4: Wipes - clean surface, 70% ethanol only | C4: ethanol wipes, surface wipes | D4: GEN | E4: =INDEX(Categories!$B$2:$B$36,MATCH(D4,Categories!$A$2:$A$36,0)) | F4: =INDEX(Categories!$D$2:$D$36,MATCH(D4,Categories!$A$2:$A$36,0)) | I4: Not if wiping up spills of anything other than ethanol. | J4: Trace ethanol only, no contamination. | K4: Medium
A5: I004 | B5: Cardboard and paper packaging (kit boxes, sleeves) | C5: kit box, carton | D5: REC | E5: =INDEX(Categories!$B$2:$B$36,MATCH(D5,Categories!$A$2:$A$36,0)) | F5: =INDEX(Categories!$D$2:$D$36,MATCH(D5,Categories!$A$2:$A$36,0)) | G5: Flatten; remove hazard labels. | J5: Clean packaging. | K5: High
A6: I005 | B6: Empty tip racks / plastic packaging - clean and unused | C6: tip box, rack | D6: REC | E6: =INDEX(Categories!$B$2:$B$36,MATCH(D6,Categories!$A$2:$A$36,0)) | F6: =INDEX(Categories!$D$2:$D$36,MATCH(D6,Categories!$A$2:$A$36,0)) | G6: Only if clean. | I6: Not if it held used consumables. | J6: Clean plastic. | K6: Medium
A7: I006 | B7: Empty reagent bottles / clean glass (rinsed) | C7: bottle, Schott, Duran, empty bottle | D7: GLS | E7: =INDEX(Categories!$B$2:$B$36,MATCH(D7,Categories!$A$2:$A$36,0)) | F7: =INDEX(Categories!$D$2:$D$36,MATCH(D7,Categories!$A$2:$A$36,0)) | G7: Triple-rinse; send rinsate to the correct liquid stream; deface label; remove cap. | I7: Do not bin unrinsed bottles that held hazardous chemicals. | J7: Rinsed empty glass is non-hazardous. | K7: Medium
A8: I007 | B8: Broken glass - uncontaminated (Pasteur pipettes, slides, coverslips) | C8: glass pipette, coverslip, microscope slide | D8: GLS | E8: =INDEX(Categories!$B$2:$B$36,MATCH(D8,Categories!$A$2:$A$36,0)) | F8: =INDEX(Categories!$D$2:$D$36,MATCH(D8,Categories!$A$2:$A$36,0)) | G8: Rigid broken-glass box only, never a bag. | H8: SHARP | J8: Sharp but not contaminated. | K8: Medium
A9: I008 | B9: Cell culture flasks, plates and dishes (non-GM, media aspirated) | C9: T75, T25, 6-well, 96-well, petri dish | D9: BIO-AUT | E9: =INDEX(Categories!$B$2:$B$36,MATCH(D9,Categories!$A$2:$A$36,0)) | F9: =INDEX(Categories!$D$2:$D$36,MATCH(D9,Categories!$A$2:$A$36,0)) | G9: Aspirate media into the biological liquid waste first; bag loosely; autoclave. | H9: BIOHAZARD | I9: No bleach, solvents or cytotoxic-treated cells in this bag. | J9: Biological material, autoclave route. | K9: High
A10: I009 | B10: Serological pipettes (plastic) - cell culture | C10: stripette, pipette | D10: BIO-AUT | E10: =INDEX(Categories!$B$2:$B$36,MATCH(D10,Categories!$A$2:$A$36,0)) | F10: =INDEX(Categories!$D$2:$D$36,MATCH(D10,Categories!$A$2:$A$36,0)) | G10: Tip-down in a rigid pipette discard tub; autoclave the tub. | H10: BIOHAZARD;SHARP | J10: Biological contact with a puncture risk. | K10: Medium
A11: I010 | B11: Pipette tips and microtubes - biological sample contact | C11: tips, eppendorf, microcentrifuge tube | D11: BIO-AUT | E11: =INDEX(Categories!$B$2:$B$36,MATCH(D11,Categories!$A$2:$A$36,0)) | F11: =INDEX(Categories!$D$2:$D$36,MATCH(D11,Categories!$A$2:$A$36,0)) | G11: Autoclave route. | H11: BIOHAZARD | I11: Not if contaminated with solvents, guanidinium, CMR agents or cytotoxics. | J11: Biological contact only. | K11: Medium
A12: I011 | B12: Gloves - biological contact (cell culture, lysates) | C12: gloves, PPE | D12: BIO-AUT | E12: =INDEX(Categories!$B$2:$B$36,MATCH(D12,Categories!$A$2:$A$36,0)) | F12: =INDEX(Categories!$D$2:$D$36,MATCH(D12,Categories!$A$2:$A$36,0)) | G12: Autoclave route. | H12: BIOHAZARD | J12: Biological contact. | K12: Medium
A13: I012 | B13: Used cryovials (empty) | C13: cryotube, freezing vial | D13: BIO-AUT | E13: =INDEX(Categories!$B$2:$B$36,MATCH(D13,Categories!$A$2:$A$36,0)) | F13: =INDEX(Categories!$D$2:$D$36,MATCH(D13,Categories!$A$2:$A$36,0)) | G13: Autoclave route. | H13: BIOHAZARD | J13: Biological contact. | K13: Medium
A14: I013 | B14: Aspirated media, PBS and trypsin washes (no hazardous additives) | C14: culture media, supernatant, DMEM, RPMI, FBS | D14: BIO-LIQ | E14: =INDEX(Categories!$B$2:$B$36,MATCH(D14,Categories!$A$2:$A$36,0)) | F14: =INDEX(Categories!$D$2:$D$36,MATCH(D14,Categories!$A$2:$A$36,0)) | G14: Inactivate with hypochlorite per your SOP then drain, or autoclave in a suitable vessel. | H14: BIOHAZARD | I14: Do not add bleach if guanidinium, acid, formaldehyde, ammonium or solvents are present. Do not autoclave after bleach is added. | J14: Biological liquid needing inactivation. | K14: High
A15: I014 | B15: Transfected / virally transduced cell waste (solids and liquids) | C15: lentivirus, transfection, GM, transduced cells | D15: BIO-GM | E15: =INDEX(Categories!$B$2:$B$36,MATCH(D15,Categories!$A$2:$A$36,0)) | F15: =INDEX(Categories!$D$2:$D$36,MATCH(D15,Categories!$A$2:$A$36,0)) | G15: Inactivate before it leaves the lab; vectors follow the containment-level SOP; label as GM. | H15: GM;BIOHAZARD | I15: Do not mix with non-GM waste if policy requires separation. | J15: GM material must be inactivated. | K15: Verify locally
A16: I015 | B16: Cell culture waste from cytotoxic drug treatment | C16: cisplatin, doxorubicin, drug treated cells, chemotherapy | D16: CYT | E16: =INDEX(Categories!$B$2:$B$36,MATCH(D16,Categories!$A$2:$A$36,0)) | F16: =INDEX(Categories!$D$2:$D$36,MATCH(D16,Categories!$A$2:$A$36,0)) | G16: Collect in the purple stream. | H16: CYTOTOXIC;TOXIC;NO_DRAIN;NO_AUTOCLAVE | I16: Do not autoclave or bleach-and-drain. | J16: Cytotoxic exposure overrides the biological route. | K16: High
A17: I016 | B17: Human / animal tissue, FFPE blocks, unfixed samples | C17: tissue, biopsy, FFPE, mouse tissue | D17: BIO-INC | E17: =INDEX(Categories!$B$2:$B$36,MATCH(D17,Categories!$A$2:$A$36,0)) | F17: =INDEX(Categories!$D$2:$D$36,MATCH(D17,Categories!$A$2:$A$36,0)) | G17: Seal, label, hold for clinical waste collection. | H17: BIOHAZARD | J17: Tissue goes to incineration. | K17: Verify locally
A18: I017 | B18: Needles and syringes (biological) | C18: needle, syringe | D18: SHP-INF | E18: =INDEX(Categories!$B$2:$B$36,MATCH(D18,Categories!$A$2:$A$36,0)) | F18: =INDEX(Categories!$D$2:$D$36,MATCH(D18,Categories!$A$2:$A$36,0)) | G18: Do not recap or bend; fill to the line only. | H18: SHARP;BIOHAZARD | J18: Sharps bin required. | K18: High
A19: I018 | B19: Scalpel / razor blades | C19: scalpel, razor, blade | D19: SHP-INF | E19: =INDEX(Categories!$B$2:$B$36,MATCH(D19,Categories!$A$2:$A$36,0)) | F19: =INDEX(Categories!$D$2:$D$36,MATCH(D19,Categories!$A$2:$A$36,0)) | G19: Fill to the line only. | H19: SHARP | I19: Not if contaminated with CMR agents (see sharps - chemical). | J19: Sharps bin required. | K19: High
A20: I019 | B20: Broken glass or slides contaminated with biological material | C20: contaminated coverslip, contaminated slide | D20: SHP-INF | E20: =INDEX(Categories!$B$2:$B$36,MATCH(D20,Categories!$A$2:$A$36,0)) | F20: =INDEX(Categories!$D$2:$D$36,MATCH(D20,Categories!$A$2:$A$36,0)) | G20: Sharps bin, not a glass box. | H20: SHARP;BIOHAZARD | J20: Contaminated sharp. | K20: Medium
A21: I020 | B21: Sharps contaminated with chemicals (e.g. EtBr gel-cutting blades, stain-contaminated glass) | C21: gel cutter, contaminated blade | D21: SHP-CHEM | E21: =INDEX(Categories!$B$2:$B$36,MATCH(D21,Categories!$A$2:$A$36,0)) | F21: =INDEX(Categories!$D$2:$D$36,MATCH(D21,Categories!$A$2:$A$36,0)) | G21: Write the contaminant on the label. | H21: SHARP;TOXIC | J21: Chemical contamination needs the chemical sharps stream. | K21: Medium
A22: I021 | B22: Polyacrylamide gels (after SDS-PAGE) | C22: SDS-PAGE gel, protein gel, Bis-Tris gel, precast gel | D22: BIO-AUT | E22: =INDEX(Categories!$B$2:$B$36,MATCH(D22,Categories!$A$2:$A$36,0)) | F22: =INDEX(Categories!$D$2:$D$36,MATCH(D22,Categories!$A$2:$A$36,0)) | G22: Collect in a sealed bag. | H22: TOXIC | I22: Do not autoclave. | J22: Local lab policy: protein gels and blot membranes go to the autoclave route. | K22: Medium
A23: I022 | B23: Unpolymerised acrylamide / bis-acrylamide solution or powder | C23: acrylamide, bis-acrylamide, gel casting solution | D23: CMR-LIQ | E23: =INDEX(Categories!$B$2:$B$36,MATCH(D23,Categories!$A$2:$A$36,0)) | F23: =INDEX(Categories!$D$2:$D$36,MATCH(D23,Categories!$A$2:$A$36,0)) | G23: Powder handled in a fume cupboard; double glove. | H23: CARCINOGEN;MUTAGEN;TOXIC;NO_DRAIN | I23: Never drain. | J23: Carcinogen and mutagen. | K23: High
A24: I023 | B24: SDS-PAGE running buffer (Tris-glycine-SDS) | C24: running buffer, Tris glycine | D24: DRAIN | E24: =INDEX(Categories!$B$2:$B$36,MATCH(D24,Categories!$A$2:$A$36,0)) | F24: =INDEX(Categories!$D$2:$D$36,MATCH(D24,Categories!$A$2:$A$36,0)) | G24: Flush with plenty of water. | I24: Not if it contains azide or other additives. | J24: Low hazard at working concentration. | K24: Medium
A25: I024 | B25: Western transfer buffer (contains methanol) | C25: transfer buffer, towbin | D25: CHEM-NH | E25: =INDEX(Categories!$B$2:$B$36,MATCH(D25,Categories!$A$2:$A$36,0)) | F25: =INDEX(Categories!$D$2:$D$36,MATCH(D25,Categories!$A$2:$A$36,0)) | H25: FLAMMABLE;ORGANIC;NONHAL;NO_DRAIN;NO_AUTOCLAVE | I25: No bleach. | J25: Methanol content; some sites allow small volumes via drain. | K25: Verify locally
A26: I025 | B26: TBS-T / PBS-T wash buffers (no azide) | C26: TBST, PBST, wash buffer | D26: DRAIN | E26: =INDEX(Categories!$B$2:$B$36,MATCH(D26,Categories!$A$2:$A$36,0)) | F26: =INDEX(Categories!$D$2:$D$36,MATCH(D26,Categories!$A$2:$A$36,0)) | G26: Flush with plenty of water. | I26: Not if it contains azide. | J26: Low hazard. | K26: Medium
A27: I026 | B27: Buffers containing sodium azide (antibody diluent, storage buffers) | C27: sodium azide, NaN3, antibody storage | D27: CHEM-AQ | E27: =INDEX(Categories!$B$2:$B$36,MATCH(D27,Categories!$A$2:$A$36,0)) | F27: =INDEX(Categories!$D$2:$D$36,MATCH(D27,Categories!$A$2:$A$36,0)) | G27: Label with azide. | H27: AZIDE;TOXIC;NO_DRAIN | I27: No acids (hydrazoic acid gas). Never drain: azide forms explosive metal azides in plumbing. | J27: Acutely toxic and reactive. | K27: High
A28: I027 | B28: Western blot membranes (PVDF / nitrocellulose) after imaging | C28: PVDF, nitrocellulose, blot | D28: BIO-AUT | E28: =INDEX(Categories!$B$2:$B$36,MATCH(D28,Categories!$A$2:$A$36,0)) | F28: =INDEX(Categories!$D$2:$D$36,MATCH(D28,Categories!$A$2:$A$36,0)) | G28: Collect with chemical solids. | I28: Do not autoclave. | J28: Local lab policy: protein gels and blot membranes go to the autoclave route. | K28: Medium
A29: I028 | B29: ECL / chemiluminescent substrate (used) | C29: ECL, luminol, Clarity | D29: CHEM-AQ | E29: =INDEX(Categories!$B$2:$B$36,MATCH(D29,Categories!$A$2:$A$36,0)) | F29: =INDEX(Categories!$D$2:$D$36,MATCH(D29,Categories!$A$2:$A$36,0)) | H29: IRRITANT;NO_DRAIN | J29: Conservative collection of reactive reagent. | K29: Medium
A30: I029 | B30: Coomassie stain / destain (methanol-acetic acid) | C30: Coomassie, destain, Brilliant Blue | D30: CHEM-NH | E30: =INDEX(Categories!$B$2:$B$36,MATCH(D30,Categories!$A$2:$A$36,0)) | F30: =INDEX(Categories!$D$2:$D$36,MATCH(D30,Categories!$A$2:$A$36,0)) | H30: FLAMMABLE;ORGANIC;NONHAL;ACID;NO_DRAIN;NO_AUTOCLAVE | I30: No bleach. | J30: Flammable with acid content; some sites split acidic fractions. | K30: Medium
A31: I030 | B31: RIPA / detergent lysis buffer with lysate (no guanidinium) | C31: RIPA, lysate, NP-40, lysis buffer | D31: CHEM-AQ | E31: =INDEX(Categories!$B$2:$B$36,MATCH(D31,Categories!$A$2:$A$36,0)) | F31: =INDEX(Categories!$D$2:$D$36,MATCH(D31,Categories!$A$2:$A$36,0)) | G31: Collect and label. | H31: IRRITANT;NO_DRAIN | I31: Not for guanidinium buffers (see lysis waste). | J31: Detergent plus biological origin; conservative. | K31: Medium
A32: I031 | B32: Agarose gels stained with ethidium bromide | C32: EtBr gel, ethidium bromide gel, DNA gel | D32: CMR-SOL | E32: =INDEX(Categories!$B$2:$B$36,MATCH(D32,Categories!$A$2:$A$36,0)) | F32: =INDEX(Categories!$D$2:$D$36,MATCH(D32,Categories!$A$2:$A$36,0)) | G32: Sealed bag. | H32: MUTAGEN;TOXIC;NO_DRAIN;NO_AUTOCLAVE | I32: Never general waste. | J32: Mutagen. | K32: High
A33: I032 | B33: TAE / TBE buffer containing ethidium bromide | C33: EtBr buffer | D33: CMR-LIQ | E33: =INDEX(Categories!$B$2:$B$36,MATCH(D33,Categories!$A$2:$A$36,0)) | F33: =INDEX(Categories!$D$2:$D$36,MATCH(D33,Categories!$A$2:$A$36,0)) | G33: Some sites filter through charcoal first. | H33: MUTAGEN;NO_DRAIN | I33: Never drain. | J33: Mutagen. | K33: High
A34: I033 | B34: Gloves, tips and paper contaminated with EtBr, DAB or other CMR agents | C34: CMR gloves, EtBr gloves | D34: CMR-SOL | E34: =INDEX(Categories!$B$2:$B$36,MATCH(D34,Categories!$A$2:$A$36,0)) | F34: =INDEX(Categories!$D$2:$D$36,MATCH(D34,Categories!$A$2:$A$36,0)) | G34: Sealed bag. | H34: MUTAGEN;NO_AUTOCLAVE | J34: CMR contamination. | K34: High
A35: I034 | B35: Agarose gels with SYBR Safe / GelRed / similar stains | C35: SYBR Safe, GelRed, safe stain | D35: CHEM-SOL | E35: =INDEX(Categories!$B$2:$B$36,MATCH(D35,Categories!$A$2:$A$36,0)) | F35: =INDEX(Categories!$D$2:$D$36,MATCH(D35,Categories!$A$2:$A$36,0)) | J35: Marketed as safer but disposal advice varies by site. | K35: Verify locally
A36: I035 | B36: TAE / TBE buffer (no stain) | C36: TAE, TBE | D36: DRAIN | E36: =INDEX(Categories!$B$2:$B$36,MATCH(D36,Categories!$A$2:$A$36,0)) | F36: =INDEX(Categories!$D$2:$D$36,MATCH(D36,Categories!$A$2:$A$36,0)) | G36: Flush with plenty of water. | I36: Not if stained with EtBr. | J36: Low hazard at working concentration. | K36: Medium
A37: I036 | B37: PCR / qPCR tubes, plates and tips with DNA template | C37: PCR, qPCR, thermocycler plate, 8-strip | D37: BIO-AUT | E37: =INDEX(Categories!$B$2:$B$36,MATCH(D37,Categories!$A$2:$A$36,0)) | F37: =INDEX(Categories!$D$2:$D$36,MATCH(D37,Categories!$A$2:$A$36,0)) | G37: Autoclave route (some sites allow general waste if non-GM and no human material). | H37: BIOHAZARD | I37: Treat as GM waste if template is recombinant. | J37: Template DNA contact. | K37: Verify locally
A38: I037 | B38: TRIzol / TRI Reagent organic phase (phenol-chloroform) | C38: TRIzol, TRI Reagent, phenol chloroform, Qiazol | D38: CHEM-HAL | E38: =INDEX(Categories!$B$2:$B$36,MATCH(D38,Categories!$A$2:$A$36,0)) | F38: =INDEX(Categories!$D$2:$D$36,MATCH(D38,Categories!$A$2:$A$36,0)) | G38: Glass or solvent-resistant container; fume cupboard. | H38: PHENOL;HALOGENATED;ORGANIC;TOXIC;CORROSIVE;GUANIDINE;NO_DRAIN;NO_AUTOCLAVE | I38: No bleach. No acids. | J38: Phenol, chloroform and guanidinium thiocyanate. | K38: High
A39: I038 | B39: TRIzol / TRI Reagent aqueous phase and lysate waste | C39: TRIzol lysate, RNA aqueous phase | D39: CHEM-GUA | E39: =INDEX(Categories!$B$2:$B$36,MATCH(D39,Categories!$A$2:$A$36,0)) | F39: =INDEX(Categories!$D$2:$D$36,MATCH(D39,Categories!$A$2:$A$36,0)) | G39: Fume cupboard. | H39: PHENOL;GUANIDINE;TOXIC;NO_DRAIN;NO_AUTOCLAVE | I39: No bleach (toxic gas). No acids. | J39: Contains guanidinium and residual phenol. | K39: High
A40: I039 | B40: Column-kit flow-through and buffers with guanidinium (lysis / binding) | C40: RLT, buffer RLT, RW1, binding buffer, Qiagen flow-through, miniprep | D40: CHEM-GUA | E40: =INDEX(Categories!$B$2:$B$36,MATCH(D40,Categories!$A$2:$A$36,0)) | F40: =INDEX(Categories!$D$2:$D$36,MATCH(D40,Categories!$A$2:$A$36,0)) | G40: Check the kit safety sheet for guanidinium buffers. | H40: GUANIDINE;TOXIC;NO_DRAIN;NO_AUTOCLAVE | I40: No bleach (toxic gas). No acids. | J40: Guanidinium salts react with bleach. | K40: High
...

Sheet Incompatibilities
A1: Rule ID | B1: Flag A | C1: Flag B | D1: Hazard | E1: Rule for the app | F1: Severity
A2: R01 | B2: BLEACH | C2: ACID | D2: Releases chlorine gas | E2: Block: never place in the same container or treat together. | F2: Critical
A3: R02 | B3: BLEACH | C3: AMMONIA | D3: Forms toxic chloramine vapours (includes ammonium salts and urea) | E3: Block. | F3: Critical
A4: R03 | B4: BLEACH | C4: GUANIDINE | D4: Releases toxic gases when guanidinium salts meet hypochlorite | E4: Block. Do not use bleach on lysis-buffer waste. | F4: Critical
A5: R04 | B5: BLEACH | C5: FORMALDEHYDE | D5: Hazardous chlorinated by-products | E5: Block. | F5: High
A6: R05 | B6: BLEACH | C6: ORGANIC | D6: Reactive and toxic chlorinated by-products (e.g. with acetone or alcohols) | E6: Block. Do not add bleach to solvent-containing waste. | F6: High
A7: R06 | B7: AZIDE | C7: ACID | D7: Forms hydrazoic acid, a toxic and explosive gas | E7: Block. | F7: Critical
A8: R07 | B8: OXIDISER | C8: ORGANIC | D8: Fire or explosion risk | E8: Block. | F8: Critical
A9: R08 | B9: ACID | C9: BASE | D9: Violent exothermic reaction | E9: Block unless a neutralisation SOP applies. | F9: High
A10: R09 | B10: HALOGENATED | C10: NONHAL | D10: Different disposal routes; mixing raises cost and risk | E10: Warn: keep in separate carboys. | F10: Segregation
A11: R10 | B11: CYTOTOXIC | C11: ANY | D11: Cytotoxic waste must stay in its own stream | E11: Block mixing with anything. | F11: Segregation
A12: R11 | B12: CMR | C12: ANY | D12: CMR agents must not enter general chemical, biological or drain streams | E12: Block mixing with anything outside CMR streams. | F12: Segregation
... A16: R15 | B16: EXPLOSIVE | C16: ANY | D16: Shock-sensitive material | E16: Block handling and mixing; escalate. | F16: Critical

Sheet Workflows
A1: Workflow | B1: Stage | C1: Item ID | D1: Item | E1: Category ID | F1: Container
A2: Western blot / SDS-PAGE | B2: Sample prep | C2: I030 | D2: =INDEX(Items!$B$2:$B$86,MATCH(C2,Items!$A$2:$A$86,0)) | E2: =INDEX(Items!$D$2:$D$86,MATCH(C2,Items!$A$2:$A$86,0)) | F2: =INDEX(Categories!$D$2:$D$36,MATCH(E2,Categories!$A$2:$A$36,0))
A3: Western blot / SDS-PAGE | B3: Sample prep | C3: I010 | D3: =INDEX(Items!$B$2:$B$86,MATCH(C3,Items!$A$2:$A$86,0)) | E3: =INDEX(Items!$D$2:$D$86,MATCH(C3,Items!$A$2:$A$86,0)) | F3: =INDEX(Categories!$D$2:$D$36,MATCH(E3,Categories!$A$2:$A$36,0))
A4: Western blot / SDS-PAGE | B4: Sample prep | C4: I011 | D4: =INDEX(Items!$B$2:$B$86,MATCH(C4,Items!$A$2:$A$86,0)) | E4: =INDEX(Items!$D$2:$D$86,MATCH(C4,Items!$A$2:$A$86,0)) | F4: =INDEX(Categories!$D$2:$D$36,MATCH(E4,Categories!$A$2:$A$36,0))
A5: Western blot / SDS-PAGE | B5: Gel casting | C5: I022 | D5: =INDEX(Items!$B$2:$B$86,MATCH(C5,Items!$A$2:$A$86,0)) | E5: =INDEX(Items!$D$2:$D$86,MATCH(C5,Items!$A$2:$A$86,0)) | F5: =INDEX(Categories!$D$2:$D$36,MATCH(E5,Categories!$A$2:$A$36,0))
A6: Western blot / SDS-PAGE | B6: Electrophoresis | C6: I021 | D6: =INDEX(Items!$B$2:$B$86,MATCH(C6,Items!$A$2:$A$86,0)) | E6: =INDEX(Items!$D$2:$D$86,MATCH(C6,Items!$A$2:$A$86,0)) | F6: =INDEX(Categories!$D$2:$D$36,MATCH(E6,Categories!$A$2:$A$36,0))
A7: Western blot / SDS-PAGE | B7: Electrophoresis | C7: I023 | D7: =INDEX(Items!$B$2:$B$86,MATCH(C7,Items!$A$2:$A$86,0)) | E7: =INDEX(Items!$D$2:$D$86,MATCH(C7,Items!$A$2:$A$86,0)) | F7: =INDEX(Categories!$D$2:$D$36,MATCH(E7,Categories!$A$2:$A$36,0))
A8: Western blot / SDS-PAGE | B8: Transfer | C8: I024 | D8: =INDEX(Items!$B$2:$B$86,MATCH(C8,Items!$A$2:$A$86,0)) | E8: =INDEX(Items!$D$2:$D$86,MATCH(C8,Items!$A$2:$A$86,0)) | F8: =INDEX(Categories!$D$2:$D$36,MATCH(E8,Categories!$A$2:$A$36,0))
A9: Western blot / SDS-PAGE | B9: Blocking and washes | C9: I025 | D9: =INDEX(Items!$B$2:$B$86,MATCH(C9,Items!$A$2:$A$86,0)) | E9: =INDEX(Items!$D$2:$D$86,MATCH(C9,Items!$A$2:$A$86,0)) | F9: =INDEX(Categories!$D$2:$D$36,MATCH(E9,Categories!$A$2:$A$36,0))
A10: Western blot / SDS-PAGE | B10: Antibody incubation | C10: I026 | D10: =INDEX(Items!$B$2:$B$86,MATCH(C10,Items!$A$2:$A$86,0)) | E10: =INDEX(Items!$D$2:$D$86,MATCH(C10,Items!$A$2:$A$86,0)) | F10: =INDEX(Categories!$D$2:$D$36,MATCH(E10,Categories!$A$2:$A$36,0))
A11: Western blot / SDS-PAGE | B11: Detection | C11: I028 | D11: =INDEX(Items!$B$2:$B$86,MATCH(C11,Items!$A$2:$A$86,0)) | E11: =INDEX(Items!$D$2:$D$86,MATCH(C11,Items!$A$2:$A$86,0)) | F11: =INDEX(Categories!$D$2:$D$36,MATCH(E11,Categories!$A$2:$A$36,0))
A12: Western blot / SDS-PAGE | B12: Detection | C12: I027 | D12: =INDEX(Items!$B$2:$B$86,MATCH(C12,Items!$A$2:$A$86,0)) | E12: =INDEX(Items!$D$2:$D$86,MATCH(C12,Items!$A$2:$A$86,0)) | F12: =INDEX(Categories!$D$2:$D$36,MATCH(E12,Categories!$A$2:$A$36,0))
A13: Western blot / SDS-PAGE | B13: Staining | C13: I029 | D13: =INDEX(Items!$B$2:$B$86,MATCH(C13,Items!$A$2:$A$86,0)) | E13: =INDEX(Items!$D$2:$D$86,MATCH(C13,Items!$A$2:$A$86,0)) | F13: =INDEX(Categories!$D$2:$D$36,MATCH(E13,Categories!$A$2:$A$36,0))
... A66: LC-MS/MS proteomics sample prep | B66: Derivatisation (e.g. acetylation) | C66: I069 | D66: =INDEX(Items!$B$2:$B$86,MATCH(C66,Items!$A$2:$A$86,0)) | E66: =INDEX(Items!$D$2:$D$86,MATCH(C66,Items!$A$2:$A$86,0)) | F66: =INDEX(Categories!$D$2:$D$36,MATCH(E66,Categories!$A$2:$A$36,0))
